<?xml version="1.0" ?>
<!-- This URDF was automatically created by SolidWorks to URDF Exporter! Originally created by Stephen Brawner (brawner@gmail.com) 
     Commit Version: 1.6.0-4-g7f85cfe  Build Version: 1.6.7995.38578
     For more information, please see http://wiki.ros.org/sw_urdf_exporter -->
<robot
  name="cubot_v2_sw2urdf">
  <link name="base_footprint"/>

  <joint name="base_footprint_joint" type="fixed">
      <origin xyz="0 0 0.068" rpy="0 0 0" />
      <parent link="base_footprint"/>
      <child link="base_link" />
  </joint>

  <link
    name="base_link">
    <inertial>
      <origin
        xyz="0.0391969072065923 -0.00101695336969354 0.0172622634177991"
        rpy="0 0 0" />
      <mass
        value="2.11133844737526" />
      <inertia
        ixx="0.00810381932898893"
        ixy="-4.04688410425005E-06"
        ixz="-2.22311181502572E-05"
        iyy="0.00515213576750178"
        iyz="2.85002049617443E-06"
        izz="0.0104376132869909" />
    </inertial>
    <visual>
      <origin
        xyz="0 0 0"
        rpy="0 0 0" />
      <geometry>
        <mesh
          filename="package://cubot/description/cubot_v2/meshes/base_link.STL" />
      </geometry>
      <material
        name="">
        <color
          rgba="1 1 1 1" />
      </material>
    </visual>
    <collision>
      <origin
        xyz="0 0 0"
        rpy="0 0 0" />
      <geometry>
        <mesh
          filename="package://cubot/description/cubot_v2/meshes/base_link.STL" />
      </geometry>
    </collision>
  </link>
  <link
    name="left_wheel_link">
    <inertial>
      <origin
        xyz="4.64739506124134E-05 2.83446131096876E-06 -0.00341416634712033"
        rpy="0 0 0" />
      <mass
        value="0.0458667465351408" />
      <inertia
        ixx="1.92244224670465E-05"
        ixy="2.88637992016539E-09"
        ixz="8.88310050215939E-10"
        iyy="1.91564476074593E-05"
        iyz="4.2649891782141E-13"
        izz="3.31656636860426E-05" />
    </inertial>
    <visual>
      <origin
        xyz="0 0 0"
        rpy="0 0 0" />
      <geometry>
        <mesh
          filename="package://cubot/description/cubot_v2/meshes/left_wheel_link.STL" />
      </geometry>
      <material
        name="">
        <color
          rgba="0.741176470588235 0.901960784313726 0.956862745098039 1" />
      </material>
    </visual>
    <collision>
      <origin
        xyz="0 0 0"
        rpy="0 0 0" />
      <geometry>
        <mesh
          filename="package://cubot/description/cubot_v2/meshes/left_wheel_link.STL" />
      </geometry>
    </collision>
  </link>
  <joint
    name="left_wheel_joint"
    type="continuous">
    <origin
      xyz="-0.0193193127809507 0.110182841531677 -0.035000000001231"
      rpy="-1.5707963267949 0 0" />
    <parent
      link="base_link" />
    <child
      link="left_wheel_link" />
    <axis
      xyz="0 0 1" />
  </joint>
  <link
    name="right_wheel_link">
    <inertial>
      <origin
        xyz="1.85059381818953E-05 -4.27269320609214E-05 -0.00341416702807762"
        rpy="0 0 0" />
      <mass
        value="0.0458667419245876" />
      <inertia
        ixx="1.91661909505543E-05"
        ixy="-2.39961843599765E-08"
        ixz="3.03062328334653E-10"
        iyy="1.92146771906765E-05"
        iyz="-8.34587388546564E-10"
        izz="3.31656621875727E-05" />
    </inertial>
    <visual>
      <origin
        xyz="0 0 0"
        rpy="0 0 0" />
      <geometry>
        <mesh
          filename="package://cubot/description/cubot_v2/meshes/right_wheel_link.STL" />
      </geometry>
      <material
        name="">
        <color
          rgba="0.741176470588235 0.901960784313726 0.956862745098039 1" />
      </material>
    </visual>
    <collision>
      <origin
        xyz="0 0 0"
        rpy="0 0 0" />
      <geometry>
        <mesh
          filename="package://cubot/description/cubot_v2/meshes/right_wheel_link.STL" />
      </geometry>
    </collision>
  </link>
  <joint
    name="right_wheel_joint"
    type="continuous">
    <origin
      xyz="-0.0193193127803636 -0.110182841532843 -0.0349999999999998"
      rpy="1.5707963267949 0 0" />
    <parent
      link="base_link" />
    <child
      link="right_wheel_link" />
    <axis
      xyz="0 0 -1" />
  </joint>
  <link
    name="caster_link">
    <inertial>
      <origin
        xyz="-4.04991856828296E-06 9.71113772729737E-10 0.0055713197499366"
        rpy="0 0 0" />
      <mass
        value="0.113354735246359" />
      <inertia
        ixx="6.51953271665009E-05"
        ixy="-5.68452254770524E-11"
        ixz="1.43198049159682E-09"
        iyy="1.97334669142784E-05"
        iyz="5.89877275324735E-13"
        izz="7.49278945986158E-05" />
    </inertial>
    <visual>
      <origin
        xyz="0 0 0"
        rpy="0 0 0" />
      <geometry>
        <mesh
          filename="package://cubot/description/cubot_v2/meshes/caster_link.STL" />
      </geometry>
      <material
        name="">
        <color
          rgba="1 1 1 1" />
      </material>
    </visual>
    <collision>
      <origin
        xyz="0 0 0"
        rpy="0 0 0" />
      <geometry>
        <mesh
          filename="package://cubot/description/cubot_v2/meshes/caster_link.STL" />
      </geometry>
    </collision>
  </link>
  <joint
    name="caster_joint"
    type="fixed">
    <origin
      xyz="0.124726113664049 0 -0.0374799999999999"
      rpy="0 0 0" />
    <parent
      link="base_link" />
    <child
      link="caster_link" />
    <axis
      xyz="0 0 0" />
  </joint>
</robot>